<?xml version="1.0"?>
<robot name="fishbot">

<!-- Robot Footprint -->
  <link name="base_footprint"/>

  <joint name="base_joint" type="fixed">
    <parent link="base_footprint"/>
    <child link="base_link"/>
    <origin xyz="0.0 0.0 0.076" rpy="0 0 0"/>
  </joint>

  <!-- 基础链接 -->
  <link name="base_link">
      <visual>
        <origin xyz="0 0 0.0" rpy="0 0 0"/>
        <geometry>
          <cylinder length="0.25" radius="0.225"/>
        </geometry>
        <material name="blue">
            <color rgba="0.1 0.1 1.0 0.5" />
        </material>
      </visual>
      <collision>
        <origin xyz="0 0 0.0" rpy="0 0 0"/>
        <geometry>
          <cylinder length="0.25" radius="0.225"/>
        </geometry>
         <material name="blue">
      	  <color rgba="0.1 0.1 1.0 0.5" /> 
         </material>
      </collision>
      <inertial>
        <mass value="1.0"/>
        <inertia ixx="0.1" ixy="0" ixz="0" iyy="0.1" iyz="0" izz="0.1"/>
      </inertial>
  </link>

  <!-- 激光雷达链接 -->
  <link name="laser_link">
      <visual>
        <origin xyz="0 0 0" rpy="0 0 0"/>
        <geometry>
          <cylinder length="0.09" radius="0.03"/>
        </geometry>
        <material name="black">
            <color rgba="0.0 0.0 0.0 0.5" />
        </material>
      </visual>
      <collision>
        <origin xyz="0 0 0" rpy="0 0 0"/>
        <geometry>
          <cylinder length="0.09" radius="0.03"/>
        </geometry>
        <material name="black">
          <color rgba="0.0 0.0 0.0 0.5" /> 
        </material>
      </collision>
      <inertial>
        <mass value="0.05"/>
        <inertia ixx="0.001" ixy="0" ixz="0" iyy="0.001" iyz="0" izz="0.001"/>
      </inertial>
  </link>

  <!-- 激光雷达连接 -->
  <joint name="laser_joint" type="fixed">
      <parent link="base_link" />
      <child link="laser_link" />
      <origin xyz="0 0 0.2" />
  </joint>
s
  <!-- IMU 传感器链接 -->
  <link name="imu_link">
      <visual>
        <origin xyz="0 0 0.0" rpy="0 0 0"/>
        <geometry>
            <box size="0.04 0.04 0.02"/>
        </geometry>
      </visual>
      <collision>
        <origin xyz="0 0 0.0" rpy="0 0 0"/>
        <geometry>
          <box size="0.04 0.04 0.02"/>
        </geometry>
      </collision>
      <inertial>
        <mass value="0.05"/>
        <inertia ixx="0.001" ixy="0" ixz="0" iyy="0.001" iyz="0" izz="0.001"/>
      </inertial>
  </link>

  <!-- IMU 传感器连接 -->
  <joint name="imu_joint" type="fixed">
      <parent link="base_link" />
      <child link="imu_link" />
      <origin xyz="0 0 0.02" />
  </joint>

  <!-- 左轮链接  -->
<link name="left_wheel_link">
      <visual>
        <origin xyz="0 0 0" rpy="1.57079 0 0"/>
        <geometry>
          <cylinder length="0.05" radius="0.09"/>
        </geometry>
        <material name="black">
            <color rgba="0.0 0.0 0.0 0.5" />
        </material>
      </visual>
      <collision>
        <origin xyz="0 0 0" rpy="1.57079 0 0"/>
        <geometry>
          <cylinder length="0.05" radius="0.09"/>
        </geometry>
          <material name="black">
            <color rgba="0.0 0.0 0.0 0.5" /> 
          </material>
      </collision>
      <inertial>
        <mass value="0.2"/>
        <inertia ixx="0.0005" ixy="0" ixz="0" iyy="0.0005" iyz="0" izz="0.001"/>
      </inertial>
  </link>

  <joint name="left_wheel_joint" type="continuous">
      <parent link="base_link" />
      <child link="left_wheel_link" />
      <origin xyz="0.0 0.1775 -0.135" />
      <axis xyz="0 1 0" />
  </joint> 

  <!-- 右轮链接 -->
   <link name="right_wheel_link">
      <visual>
        <origin xyz="0 0 0" rpy="1.57079 0 0"/>
        <geometry>
          <cylinder length="0.05" radius="0.09"/>
        </geometry>
        <material name="black">
            <color rgba="0.0 0.0 0.0 0.5" />
        </material>
      </visual>
      <collision>
        <origin xyz="0 0 0" rpy="1.57079 0 0"/>
        <geometry>
          <cylinder length="0.05" radius="0.09"/>
        </geometry>
          <material name="black">
            <color rgba="0.0 0.0 0.0 0.5" /> 
          </material>
      </collision>
      <inertial>
        <mass value="0.2"/>
        <inertia ixx="0.0005" ixy="0" ixz="0" iyy="0.0005" iyz="0" izz="0.001"/>
      </inertial>
  </link>

  <joint name="right_wheel_joint" type="continuous">
      <parent link="base_link" />
      <child link="right_wheel_link" />
      <origin xyz="0.0 -0.1775 -0.135" />
      <axis xyz="0 1 0" />
  </joint>

  <!-- 转向轮链接 -->
  <link name="caster1_link">
    <visual>
      <origin xyz="0 0 0" rpy="1.57079 0 0"/>
      <geometry>
          <sphere radius="0.04"/>
      </geometry>
      <material name="black">
        <color rgba="0.0 0.0 0.0 0.5" />
      </material>
    </visual>
    <collision>
      <origin xyz="0 0 0" rpy="1.57079 0 0"/>
      <geometry>
        <sphere radius="0.04"/>
      </geometry>
        <material name="black">
          <color rgba="0.0 0.0 0.0 0.5" /> 
        </material>
    </collision>
    <inertial>
      <mass value="0.05"/>
      <inertia ixx="0.0001" ixy="0" ixz="0" iyy="0.0001" iyz="0" izz="0.0001"/>
    </inertial>
  </link>

  <joint name="caster1_joint" type="fixed">
      <parent link="base_link" />
      <child link="caster1_link" />
      <origin xyz="0.15 0.15 -0.15" />
      <axis xyz="0 1 0" />
  </joint>

  <!-- 第二个转向轮链接 -->
  <link name="caster2_link">
    <visual>
      <origin xyz="0 0 0" rpy="1.57079 0 0"/>
      <geometry>
          <sphere radius="0.04"/>
      </geometry>
      <material name="black">
        <color rgba="0.0 0.0 0.0 0.5" />
      </material>
    </visual>
    <collision>
      <origin xyz="0 0 0" rpy="1.57079 0 0"/>
      <geometry>
        <sphere radius="0.04"/>
      </geometry>
    </collision>
    <inertial>
      <mass value="0.05"/>
      <inertia ixx="0.0001" ixy="0" ixz="0" iyy="0.0001" iyz="0" izz="0.0001"/>
    </inertial>
  </link>

  <joint name="caster2_joint" type="fixed">
      <parent link="base_link" />
      <child link="caster2_link" />
      <origin xyz="0.15 -0.15 -0.15" />
      <axis xyz="0 1 0" />
  </joint>

  <!-- 第三个转向轮链接 -->
  <link name="caster3_link">
    <visual>
      <origin xyz="0 0 0" rpy="1.57079 0 0"/>
      <geometry>
          <sphere radius="0.04"/>
      </geometry>
      <material name="black">
        <color rgba="0.0 0.0 0.0 0.5" />
      </material>
    </visual>
    <collision>
      <origin xyz="0 0 0" rpy="1.57079 0 0"/>
      <geometry>
        <sphere radius="0.04"/>
      </geometry>
    </collision>
    <inertial>
      <mass value="0.05"/>
      <inertia ixx="0.0001" ixy="0" ixz="0" iyy="0.0001" iyz="0" izz="0.0001"/>
    </inertial>
  </link>

  <joint name="caster3_joint" type="fixed">
      <parent link="base_link" />
      <child link="caster3_link" />
      <origin xyz="-0.205 0 -0.15" />
      <axis xyz="0 1 0" />
  </joint>