<?xml version="1.0"?>
<robot name="fishbot">

<!-- Robot Footprint -->
  <link name="base_footprint"/>

  <joint name="base_joint" type="fixed">
    <parent link="base_footprint"/>
    <child link="base_link"/>
    <origin xyz="0.0 0.0 0.076" rpy="0 0 0"/>
  </joint>

  <!-- 基础链接 -->
  <link name="base_link">
      <visual>
        <origin xyz="0 0 0.0" rpy="0 0 0"/>
        <geometry>
          <cylinder length="0.25" radius="0.225"/>
        </geometry>
        <material name="blue">
            <color rgba="0.1 0.1 1.0 0.5" />
        </material>
      </visual>
      <collision>
        <origin xyz="0 0 0.0" rpy="0 0 0"/>
        <geometry>
          <cylinder length="0.25" radius="0.225"/>
        </geometry>
         <material name="blue">
      	  <color rgba="0.1 0.1 1.0 0.5" /> 
         </material>
      </collision>
      <inertial>
        <mass value="1.0"/>
        <inertia ixx="0.1" ixy="0" ixz="0" iyy="0.1" iyz="0" izz="0.1"/>
      </inertial>
  </link>

  <!-- 激光雷达链接 -->
  <link name="laser_link">
      <visual>
        <origin xyz="0 0 0" rpy="0 0 0"/>
        <geometry>
          <cylinder length="0.09" radius="0.03"/>
        </geometry>
        <material name="black">
            <color rgba="0.0 0.0 0.0 0.5" />
        </material>
      </visual>
      <collision>
        <origin xyz="0 0 0" rpy="0 0 0"/>
        <geometry>
          <cylinder length="0.09" radius="0.03"/>
        </geometry>
        <material name="black">
          <color rgba="0.0 0.0 0.0 0.5" /> 
        </material>
      </collision>
      <inertial>
        <mass value="0.05"/>
        <inertia ixx="0.001" ixy="0" ixz="0" iyy="0.001" iyz="0" izz="0.001"/>
      </inertial>
  </link>

  <!-- 激光雷达连接 -->
  <joint name="laser_joint" type="fixed">
      <parent link="base_link" />
      <child link="laser_link" />
      <origin xyz="0 0 0.175" />
  </joint>
s
  <!-- IMU 传感器链接 -->
  <link name="imu_link">
      <visual>
        <origin xyz="0 0 0.0" rpy="0 0 0"/>
        <geometry>
            <box size="0.04 0.04 0.02"/>
        </geometry>
      </visual>
      <collision>
        <origin xyz="0 0 0.0" rpy="0 0 0"/>
        <geometry>
          <box size="0.04 0.04 0.02"/>
        </geometry>
      </collision>
      <inertial>
        <mass value="0.05"/>
        <inertia ixx="0.001" ixy="0" ixz="0" iyy="0.001" iyz="0" izz="0.001"/>
      </inertial>
  </link>

  <!-- IMU 传感器连接 -->
  <joint name="imu_joint" type="fixed">
      <parent link="base_link" />
      <child link="imu_link" />
      <origin xyz="0 0 0.02" />
  </joint>

  <!-- 左轮链接 -->
  <link name="left_wheel_link">
      <visual>
        <origin xyz="0 0 0" rpy="1.57079 0 0"/>
        <geometry>
          <cylinder length="0.05" radius="0.09"/>
        </geometry>
        <material name="black">
            <color rgba="0.0 0.0 0.0 0.5" />
        </material>
      </visual>
      <collision>
        <origin xyz="0 0 0" rpy="1.57079 0 0"/>
        <geometry>
          <cylinder length="0.05" radius="0.09"/>
        </geometry>
          <material name="black">
            <color rgba="0.0 0.0 0.0 0.5" /> 
          </material>
      </collision>
      <inertial>
        <mass value="0.2"/>
        <inertia ixx="0.0005" ixy="0" ixz="0" iyy="0.0005" iyz="0" izz="0.001"/>
      </inertial>
  </link>

  <joint name="left_wheel_joint" type="continuous">
      <parent link="base_link" />
      <child link="left_wheel_link" />
      <origin xyz="0.0 0.1775 -0.135" />
      <axis xyz="0 1 0" />
  </joint>

  <!-- 右轮链接 -->
  <link name="right_wheel_link">
      <visual>
        <origin xyz="0 0 0" rpy="1.57079 0 0"/>
        <geometry>
          <cylinder length="0.05" radius="0.09"/>
        </geometry>
        <material name="black">
            <color rgba="0.0 0.0 0.0 0.5" />
        </material>
      </visual>
      <collision>
        <origin xyz="0 0 0" rpy="1.57079 0 0"/>
        <geometry>
          <cylinder length="0.05" radius="0.09"/>
        </geometry>
          <material name="black">
            <color rgba="0.0 0.0 0.0 0.5" /> 
          </material>
      </collision>
      <inertial>
        <mass value="0.2"/>
        <inertia ixx="0.0005" ixy="0" ixz="0" iyy="0.0005" iyz="0" izz="0.001"/>
      </inertial>
  </link>

  <joint name="right_wheel_joint" type="continuous">
      <parent link="base_link" />
      <child link="right_wheel_link" />
      <origin xyz="0.0 -0.1775 -0.135" />
      <axis xyz="0 1 0" />
  </joint>

  <!-- 转向轮链接 -->
  <!-- <link name="caster1_link">
    <visual>
      <origin xyz="0 0 0" rpy="1.57079 0 0"/>
      <geometry>
          <sphere radius="0.04"/>
      </geometry>
      <material name="black">
        <color rgba="0.0 0.0 0.0 0.5" />
      </material>
    </visual>
    <collision>
      <origin xyz="0 0 0" rpy="1.57079 0 0"/>
      <geometry>
        <sphere radius="0.04"/>
      </geometry>
        <material name="black">
          <color rgba="0.0 0.0 0.0 0.5" /> 
        </material>
    </collision>
    <inertial>
      <mass value="0.05"/>
      <inertia ixx="0.0001" ixy="0" ixz="0" iyy="0.0001" iyz="0" izz="0.0001"/>
    </inertial>
  </link>

  <joint name="caster1_joint" type="fixed">
      <parent link="base_link" />
      <child link="caster1_link" />
      <origin xyz="0.15 0.15 -0.15" />
      <axis xyz="0 1 0" />
  </joint> -->

  <!-- 第二个转向轮链接 -->
  <!-- <link name="caster2_link">
    <visual>
      <origin xyz="0 0 0" rpy="1.57079 0 0"/>
      <geometry>
          <sphere radius="0.04"/>
      </geometry>
      <material name="black">
        <color rgba="0.0 0.0 0.0 0.5" />
      </material>
    </visual>
    <collision>
      <origin xyz="0 0 0" rpy="1.57079 0 0"/>
      <geometry>
        <sphere radius="0.04"/>
      </geometry>
    </collision>
    <inertial>
      <mass value="0.05"/>
      <inertia ixx="0.0001" ixy="0" ixz="0" iyy="0.0001" iyz="0" izz="0.0001"/>
    </inertial>
  </link>

  <joint name="caster2_joint" type="fixed">
      <parent link="base_link" />
      <child link="caster2_link" />
      <origin xyz="0.15 -0.15 -0.15" />
      <axis xyz="0 1 0" />
  </joint> -->

  <!-- 第三个转向轮链接 -->
  <link name="caster3_link">
    <visual>
      <origin xyz="0 0 0" rpy="1.57079 0 0"/>
      <geometry>
          <sphere radius="0.04"/>
      </geometry>
      <material name="black">
        <color rgba="0.0 0.0 0.0 0.5" />
      </material>
    </visual>
    <collision>
      <origin xyz="0 0 0" rpy="1.57079 0 0"/>
      <geometry>
        <sphere radius="0.04"/>
      </geometry>
    </collision>
    <inertial>
      <mass value="0.05"/>
      <inertia ixx="0.0001" ixy="0" ixz="0" iyy="0.0001" iyz="0" izz="0.0001"/>
    </inertial>
  </link>

  <joint name="caster3_joint" type="fixed">
      <parent link="base_link" />
      <child link="caster3_link" />
      <origin xyz="-0.205 0 -0.15" />
      <axis xyz="0 1 0" />
  </joint>

  <!-- Gazebo插件配置 -->
  <gazebo>
    <plugin name="diff_drive" filename="libgazebo_ros_diff_drive.so">
      <ros>
        <namespace>/</namespace>
        <remapping>cmd_vel:=cmd_vel</remapping>
        <remapping>odom:=odom</remapping>
      </ros>
      <update_rate>30</update_rate>
      <left_joint>left_wheel_joint</left_joint>
      <right_joint>right_wheel_joint</right_joint>
      <wheel_separation>0.2</wheel_separation>
      <wheel_diameter>0.18</wheel_diameter> <!-- 修改后的直径 -->
      <max_wheel_torque>20</max_wheel_torque>
      <max_wheel_acceleration>1.0</max_wheel_acceleration>
      <publish_odom>true</publish_odom>
      <publish_odom_tf>true</publish_odom_tf>
      <publish_wheel_tf>true</publish_wheel_tf>
      <odometry_frame>odom</odometry_frame>
      <robot_base_frame>base_footprint</robot_base_frame>
    </plugin>
  </gazebo>

  <gazebo reference="imu_link">
      <sensor name="imu_sensor" type="imu">
      <plugin filename="libgazebo_ros_imu_sensor.so" name="imu_plugin">
          <ros>
            <namespace>/</namespace>
            <remapping>~/out:=imu</remapping>
          </ros>
          <initial_orientation_as_reference>false</initial_orientation_as_reference>
        </plugin>
        <always_on>true</always_on>
        <update_rate>100</update_rate>
        <visualize>true</visualize>
        <imu>
          <angular_velocity>
            <x>
              <noise type="gaussian">
                <mean>0.0</mean>
                <stddev>2e-4</stddev>
                <bias_mean>0.0000075</bias_mean>
                <bias_stddev>0.0000008</bias_stddev>
              </noise>
            </x>
            <y>
              <noise type="gaussian">
                <mean>0.0</mean>
                <stddev>2e-4</stddev>
                <bias_mean>0.0000075</bias_mean>
                <bias_stddev>0.0000008</bias_stddev>
              </noise>
            </y>
            <z>
              <noise type="gaussian">
                <mean>0.0</mean>
                <stddev>2e-4</stddev>
                <bias_mean>0.0000075</bias_mean>
                <bias_stddev>0.0000008</bias_stddev>
              </noise>
            </z>
          </angular_velocity>
          <linear_acceleration>
            <x>
              <noise type="gaussian">
                <mean>0.0</mean>
                <stddev>1.7e-2</stddev>
                <bias_mean>0.1</bias_mean>
                <bias_stddev>0.001</bias_stddev>
              </noise>
            </x>
            <y>
              <noise type="gaussian">
                <mean>0.0</mean>
                <stddev>1.7e-2</stddev>
                <bias_mean>0.1</bias_mean>
                <bias_stddev>0.001</bias_stddev>
              </noise>
            </y>
            <z>
              <noise type="gaussian">
                <mean>0.0</mean>
                <stddev>1.7e-2</stddev>
                <bias_mean>0.1</bias_mean>
                <bias_stddev>0.001</bias_stddev>
              </noise>
            </z>
          </linear_acceleration>
        </imu>
      </sensor>
    </gazebo>

  <!-- 激光雷达传感器插件 -->
  <gazebo reference="laser_link">
      <sensor name="laser_sensor" type="ray">
      <always_on>true</always_on>
      <visualize>true</visualize>
      <update_rate>10</update_rate>
      <pose>0 0 0.075 0 0 0</pose>
      <ray>
          <scan>
            <horizontal>
              <samples>360</samples>
              <resolution>1.000000</resolution>
              <min_angle>0.000000</min_angle>
              <max_angle>6.280000</max_angle>
            </horizontal>
          </scan>
          <range>
            <min>0.120000</min>
            <max>3.5</max>
            <resolution>0.015000</resolution>
          </range>
          <noise>
            <type>gaussian</type>
            <mean>0.0</mean>
            <stddev>0.01</stddev>
          </noise>
      </ray>

      <plugin name="laserscan" filename="libgazebo_ros_ray_sensor.so">
        <ros>
          <remapping>~/out:=scan</remapping>
        </ros>
        <output_type>sensor_msgs/LaserScan</output_type>
        <frame_name>laser_link</frame_name>
      </plugin>
      </sensor>
    </gazebo>
</robot>
